Workbook

Sheet Assumptions
A1: Next plc — 3-Statement Financial Model | Assumptions
A2: Colour guide: Blue = hardcoded input Black = formula Green = cross-sheet link
A3: INCOME STATEMENT ASSUMPTIONS
A4: Revenue Growth Rate | B4: — | C4: — | D4: — | E4: 0.06 | F4: 0.07 | G4: 0.07
A5: Gross Margin (%) | B5: 0.45 | C5: 0.45 | D5: 0.45 | E5: 0.45 | F5: 0.45 | G5: 0.45
A6: EBITDA Margin (%) | B6: 0.25 | C6: 0.25 | D6: 0.25 | E6: 0.25 | F6: 0.25 | G6: 0.25
A7: D&A as % of Revenue | B7: 0.045 | C7: 0.045 | D7: 0.045 | E7: 0.045 | F7: 0.045 | G7: 0.045
A8: Tax Rate (%) | B8: 0.25 | C8: 0.25 | D8: 0.25 | E8: 0.25 | F8: 0.25 | G8: 0.25
A10: BALANCE SHEET ASSUMPTIONS (single value applies to all years)
A11: Days Sales Outstanding (DSO) | B11: 83 | C11: =B11 -> 83 | D11: =B11 -> 83 | E11: =B11 -> 83 | F11: =B11 -> 83 | G11: =B11 -> 83
A12: Days Inventory Outstanding (DIO) | B12: 64 | C12: =B12 -> 64 | D12: =B12 -> 64 | E12: =B12 -> 64 | F12: =B12 -> 64 | G12: =B12 -> 64
A13: Days Payable Outstanding (DPO) | B13: 53 | C13: =B13 -> 53 | D13: =B13 -> 53 | E13: =B13 -> 53 | F13: =B13 -> 53 | G13: =B13 -> 53
A14: Capex as % of Revenue | B14: 0.05 | C14: =B14 -> 0.05 | D14: =B14 -> 0.05 | E14: =B14 -> 0.05 | F14: =B14 -> 0.05 | G14: =B14 -> 0.05
A16: DEBT & FINANCING
A17: Opening Debt Balance FY2022A (£m) | B17: 1200
A18: Interest Rate on Debt (%) | B18: 0.065 | C18: =B18 -> 0.065 | D18: =B18 -> 0.065 | E18: =B18 -> 0.065 | F18: =B18 -> 0.065 | G18: =B18 -> 0.065
A20: DIVIDENDS
A21: Dividend Payout Ratio (%) | B21: 0.5 | C21: =B21 -> 0.5 | D21: =B21 -> 0.5 | E21: =B21 -> 0.5 | F21: =B21 -> 0.5 | G21: =B21 -> 0.5
A23: ⚠ Enter yellow cells only. All other cells are formula-driven. Source data from Next plc Annual Reports.

Sheet Income Statement
A1: Next plc — Income Statement (£m)
A2: All figures in £m | A = Actual | E = Estimated (formula-driven from Assumptions)
B3: FY2022A | C3: FY2023A | D3: FY2024A | E3: FY2025E | F3: FY2026E | G3: FY2027E
A5: Revenue | B5: 4800 | C5: 5200 | D5: 5700 | E5: =D5*(1+Assumptions!E4) -> 6042 | F5: =E5*(1+Assumptions!F4) -> 6464.94 | G5: =F5*(1+Assumptions!G4) -> 6917.4858
A6: Cost of Goods Sold | B6: 2640 | C6: 2860 | D6: 3135 | E6: =E5*(1-Assumptions!E5) -> 3323.1 | F6: =F5*(1-Assumptions!F5) -> 3555.717 | G6: =G5*(1-Assumptions!G5) -> 3804.6172
A7: Gross Profit | B7: =B5-B6 -> 2160 | C7: =C5-C6 -> 2340 | D7: =D5-D6 -> 2565 | E7: =E5-E6 -> 2718.9 | F7: =F5-F6 -> 2909.223 | G7: =G5-G6 -> 3112.8686
A8: Gross Margin % | B8: =IFERROR(B7/B5,"-") -> 0.45 | C8: =IFERROR(C7/C5,"-") -> 0.45 | D8: =IFERROR(D7/D5,"-") -> 0.45 | E8: =IFERROR(E7/E5,"-") -> 0.45 | F8: =IFERROR(F7/F5,"-") -> 0.45 | G8: =IFERROR(G7/G5,"-") -> 0.45
A10: Operating Expenses (SG&A) | B10: 1250 | C10: 1350 | D10: 1450 | E10: =IFERROR(E7-E5*Assumptions!E6,0) -> 1208.4 | F10: =IFERROR(F7-F5*Assumptions!F6,0) -> 1292.988 | G10: =IFERROR(G7-G5*Assumptions!G6,0) -> 1383.4972
A11: EBITDA | B11: =B7-B10 -> 910 | C11: =C7-C10 -> 990 | D11: =D7-D10 -> 1115 | E11: =E7-E10 -> 1510.5 | F11: =F7-F10 -> 1616.235 | G11: =G7-G10 -> 1729.3715
A12: EBITDA Margin % | B12: =IFERROR(B11/B5,"-") -> 0.18958333 | C12: =IFERROR(C11/C5,"-") -> 0.19038462 | D12: =IFERROR(D11/D5,"-") -> 0.19561404 | E12: =IFERROR(E11/E5,"-") -> 0.25 | F12: =IFERROR(F11/F5,"-") -> 0.25 | G12: =IFERROR(G11/G5,"-") -> 0.25
A14: Depreciation & Amortisation | B14: 220 | C14: 240 | D14: 260 | E14: =E5*Assumptions!E7 -> 271.89 | F14: =F5*Assumptions!F7 -> 290.9223 | G14: =G5*Assumptions!G7 -> 311.28686
A15: EBIT (Operating Profit) | B15: =B11-B14 -> 690 | C15: =C11-C14 -> 750 | D15: =D11-D14 -> 855 | E15: =E11-E14 -> 1238.61 | F15: =F11-F14 -> 1325.3127 | G15: =G11-G14 -> 1418.0846
A16: EBIT Margin % | B16: =IFERROR(B15/B5,"-") -> 0.14375 | C16: =IFERROR(C15/C5,"-") -> 0.14423077 | D16: =IFERROR(D15/D5,"-") -> 0.15 | E16: =IFERROR(E15/E5,"-") -> 0.205 | F16: =IFERROR(F15/F5,"-") -> 0.205 | G16: =IFERROR(G15/G5,"-") -> 0.205
A18: Net Interest Expense | B18: 75 | C18: 80 | D18: 85 | E18: ='Balance Sheet'!D25*Assumptions!$B$18 -> 71.5 | F18: ='Balance Sheet'!E25*Assumptions!$B$18 -> 71.5 | G18: ='Balance Sheet'!F25*Assumptions!$B$18 -> 71.5
A19: Profit Before Tax | B19: =B15-B18 -> 615 | C19: =C15-C18 -> 670 | D19: =D15-D18 -> 770 | E19: =E15-E18 -> 1167.11 | F19: =F15-F18 -> 1253.8127 | G19: =G15-G18 -> 1346.5846
A20: Income Tax Expense | B20: 135 | C20: 150 | D20: 170 | E20: =MAX(0,E19)*Assumptions!E8 -> 291.7775 | F20: =MAX(0,F19)*Assumptions!F8 -> 313.45318 | G20: =MAX(0,G19)*Assumptions!G8 -> 336.64615
A21: NET INCOME | B21: =B19-B20 -> 480 | C21: =C19-C20 -> 520 | D21: =D19-D20 -> 600 | E21: =E19-E20 -> 875.3325 | F21: =F19-F20 -> 940.35953 | G21: =G19-G20 -> 1009.9384
A22: Net Margin % | B22: =IFERROR(B21/B5,"-") -> 0.1 | C22: =IFERROR(C21/C5,"-") -> 0.1 | D22: =IFERROR(D21/D5,"-") -> 0.10526316 | E22: =IFERROR(E21/E5,"-") -> 0.14487463 | F22: =IFERROR(F21/F5,"-") -> 0.14545526 | G22: =IFERROR(G21/G5,"-") -> 0.14599791

Sheet Balance Sheet
A1: Next plc — Balance Sheet (£m)
A2: All figures in £m | Yellow = input cell (enter from annual report) | Black = formula
B3: FY2022A | C3: FY2023A | D3: FY2024A | E3: FY2025E | F3: FY2026E | G3: FY2027E
A5: ASSETS
A6: Cash & Equivalents | B6: 350 | C6: 400 | D6: 450 | E6: ='Cash Flow'!E25 -> 793.37378 | F6: ='Cash Flow'!F25 -> 1128.0431 | G6: ='Cash Flow'!G25 -> 1488.0161
A7: Trade Receivables | B7: 1100 | C7: 1200 | D7: 1300 | E7: ='Income Statement'!E5*Assumptions!$B$11/365 -> 1373.9342 | F7: ='Income Statement'!F5*Assumptions!$B$11/365 -> 1470.1096 | G7: ='Income Statement'!G5*Assumptions!$B$11/365 -> 1573.0173
A8: Inventories | B8: 550 | C8: 580 | D8: 620 | E8: ='Income Statement'!E6*Assumptions!$B$12/365 -> 582.68055 | F8: ='Income Statement'!F6*Assumptions!$B$12/365 -> 623.46819 | G8: ='Income Statement'!G6*Assumptions!$B$12/365 -> 667.11096
A9: Other Current Assets | B9: 80 | C9: 85 | D9: 90 | E9: =D9 -> 90 | F9: =E9 -> 90 | G9: =F9 -> 90
A10: Total Current Assets | B10: =SUM(B6:B9) -> 2080 | C10: =SUM(C6:C9) -> 2265 | D10: =SUM(D6:D9) -> 2460 | E10: =SUM(E6:E9) -> 2839.9886 | F10: =SUM(F6:F9) -> 3311.6209 | G10: =SUM(G6:G9) -> 3818.1444
A12: PP&E (Gross) | B12: 1800 | C12: 1900 | D12: 2000 | E12: =D12+'Income Statement'!E5*Assumptions!$B$14 -> 2302.1 | F12: =E12+'Income Statement'!F5*Assumptions!$B$14 -> 2625.347 | G12: =F12+'Income Statement'!G5*Assumptions!$B$14 -> 2971.2213
A13: Accumulated Depreciation (negative) | B13: -600 | C13: -820 | D13: -1050 | E13: =D13-'Income Statement'!E14 -> -1321.89 | F13: =E13-'Income Statement'!F14 -> -1612.8123 | G13: =F13-'Income Statement'!G14 -> -1924.0992
A14: PP&E (Net) | B14: =B12+B13 -> 1200 | C14: =C12+C13 -> 1080 | D14: =D12+D13 -> 950 | E14: =E12+E13 -> 980.21 | F14: =F12+F13 -> 1012.5347 | G14: =G12+G13 -> 1047.1221
A15: Other Non-Current Assets | B15: 200 | C15: 210 | D15: 220 | E15: =D15 -> 220 | F15: =E15 -> 220 | G15: =F15 -> 220
A16: Total Non-Current Assets | B16: =B14+B15 -> 1400 | C16: =C14+C15 -> 1290 | D16: =D14+D15 -> 1170 | E16: =E14+E15 -> 1200.21 | F16: =F14+F15 -> 1232.5347 | G16: =G14+G15 -> 1267.1221
A18: TOTAL ASSETS | B18: =B10+B16 -> 3480 | C18: =C10+C16 -> 3555 | D18: =D10+D16 -> 3630 | E18: =E10+E16 -> 4040.1986 | F18: =F10+F16 -> 4544.1556 | G18: =G10+G16 -> 5085.2665
A20: LIABILITIES
A21: Trade Payables | B21: 450 | C21: 480 | D21: 510 | E21: ='Income Statement'!E6*Assumptions!$B$13/365 -> 482.53233 | F21: ='Income Statement'!F6*Assumptions!$B$13/365 -> 516.30959 | G21: ='Income Statement'!G6*Assumptions!$B$13/365 -> 552.45126
A22: Other Current Liabilities | B22: 300 | C22: 320 | D22: 340 | E22: =D22 -> 340 | F22: =E22 -> 340 | G22: =F22 -> 340
A23: Total Current Liabilities | B23: =SUM(B21:B22) -> 750 | C23: =SUM(C21:C22) -> 800 | D23: =SUM(D21:D22) -> 850 | E23: =SUM(E21:E22) -> 822.53233 | F23: =SUM(F21:F22) -> 856.30959 | G23: =SUM(G21:G22) -> 892.45126
A25: Long-Term Debt | B25: 1200 | C25: 1150 | D25: 1100 | E25: =D25 -> 1100 | F25: =E25 -> 1100 | G25: =F25 -> 1100
A26: Other Non-Current Liabilities | B26: 150 | C26: 155 | D26: 160 | E26: =D26 -> 160 | F26: =E26 -> 160 | G26: =F26 -> 160
A27: Total Non-Current Liabilities | B27: =SUM(B25:B26) -> 1350 | C27: =SUM(C25:C26) -> 1305 | D27: =SUM(D25:D26) -> 1260 | E27: =SUM(E25:E26) -> 1260 | F27: =SUM(F25:F26) -> 1260 | G27: =SUM(G25:G26) -> 1260
A29: TOTAL LIABILITIES | B29: =B23+B27 -> 2100 | C29: =C23+C27 -> 2105 | D29: =D23+D27 -> 2110 | E29: =E23+E27 -> 2082.5323 | F29: =F23+F27 -> 2116.3096 | G29: =G23+G27 -> 2152.4513
A31: EQUITY
A32: Share Capital & Reserves | B32: 500 | C32: 500 | D32: 500 | E32: =D32 -> 500 | F32: =E32 -> 500 | G32: =F32 -> 500
A33: Retained Earnings | B33: 880 | C33: 970 | D33: 1020 | E33: =D33+'Income Statement'!E21-('Income Statement'!E21*Assumptions!$B$21) -> 1457.6662 | F33: =E33+'Income Statement'!F21-('Income Statement'!F21*Assumptions!$B$21) -> 1927.846 | G33: =F33+'Income Statement'!G21-('Income Statement'!G21*Assumptions!$B$21) -> 2432.8152
A34: Total Equity | B34: =B32+B33 -> 1380 | C34: =C32+C33 -> 1470 | D34: =D32+D33 -> 1520 | E34: =E32+E33 -> 1957.6662 | F34: =F32+F33 -> 2427.846 | G34: =G32+G33 -> 2932.8152
A36: TOTAL LIABILITIES & EQUITY | B36: =B29+B34 -> 3480 | C36: =C29+C34 -> 3575 | D36: =D29+D34 -> 3630 | E36: =E29+E34 -> 4040.1986 | F36: =F29+F34 -> 4544.1556 | G36: =G29+G34 -> 5085.2665
A37: Balance Check (must = 0) | B37: =B18-B36 -> 0 | C37: =C18-C36 -> -20 | D37: =D18-D36 -> 0 | E37: =E18-E36 -> 0 | F37: =F18-F36 -> 0 | G37: =G18-G36 -> 0

Sheet Cash Flow
A1: Next plc — Cash Flow Statement (£m)
A2: All figures in £m | Fully formula-driven for all years
B3: FY2022A | C3: FY2023A | D3: FY2024A | E3: FY2025E | F3: FY2026E | G3: FY2027E
A4: OPERATING ACTIVITIES
A5: Net Income | B5: ='Income Statement'!B21 -> 480 | C5: ='Income Statement'!C21 -> 520 | D5: ='Income Statement'!D21 -> 600 | E5: ='Income Statement'!E21 -> 875.3325 | F5: ='Income Statement'!F21 -> 940.35953 | G5: ='Income Statement'!G21 -> 1009.9384
A6: Add: Depreciation & Amortisation | B6: ='Income Statement'!B14 -> 220 | C6: ='Income Statement'!C14 -> 240 | D6: ='Income Statement'!D14 -> 260 | E6: ='Income Statement'!E14 -> 271.89 | F6: ='Income Statement'!F14 -> 290.9223 | G6: ='Income Statement'!G14 -> 311.28686
A7: (Increase) / Decrease in Trade Receivables | B7: 0 | C7: =-('Balance Sheet'!C7-'Balance Sheet'!B7) -> -100 | D7: =-('Balance Sheet'!D7-'Balance Sheet'!C7) -> -100 | E7: =-('Balance Sheet'!E7-'Balance Sheet'!D7) -> -73.934247 | F7: =-('Balance Sheet'!F7-'Balance Sheet'!E7) -> -96.175397 | G7: =-('Balance Sheet'!G7-'Balance Sheet'!F7) -> -102.90768
A8: (Increase) / Decrease in Inventories | B8: 0 | C8: =-('Balance Sheet'!C8-'Balance Sheet'!B8) -> -30 | D8: =-('Balance Sheet'!D8-'Balance Sheet'!C8) -> -40 | E8: =-('Balance Sheet'!E8-'Balance Sheet'!D8) -> 37.319452 | F8: =-('Balance Sheet'!F8-'Balance Sheet'!E8) -> -40.787638 | G8: =-('Balance Sheet'!G8-'Balance Sheet'!F8) -> -43.642773
A9: Increase / (Decrease) in Trade Payables | B9: 0 | C9: ='Balance Sheet'!C21-'Balance Sheet'!B21 -> 30 | D9: ='Balance Sheet'!D21-'Balance Sheet'!C21 -> 30 | E9: ='Balance Sheet'!E21-'Balance Sheet'!D21 -> -27.467671 | F9: ='Balance Sheet'!F21-'Balance Sheet'!E21 -> 33.777263 | G9: ='Balance Sheet'!G21-'Balance Sheet'!F21 -> 36.141671
A10: Other Working Capital / Adjustments | B10: 0 | C10: 0 | D10: 0 | E10: 0 | F10: 0 | G10: 0
A11: Cash from Operating Activities | B11: =SUM(B5:B10) -> 700 | C11: =SUM(C5:C10) -> 660 | D11: =SUM(D5:D10) -> 750 | E11: =SUM(E5:E10) -> 1083.14 | F11: =SUM(F5:F10) -> 1128.0961 | G11: =SUM(G5:G10) -> 1210.8165
A13: INVESTING ACTIVITIES
A14: Capital Expenditure (Capex) | B14: =-'Income Statement'!B5*Assumptions!$B$14 -> -240 | C14: =-'Income Statement'!C5*Assumptions!$B$14 -> -260 | D14: =-'Income Statement'!D5*Assumptions!$B$14 -> -285 | E14: =-'Income Statement'!E5*Assumptions!$B$14 -> -302.1 | F14: =-'Income Statement'!F5*Assumptions!$B$14 -> -323.247 | G14: =-'Income Statement'!G5*Assumptions!$B$14 -> -345.87429
A15: Other Investing | B15: 0 | C15: 0 | D15: 0 | E15: 0 | F15: 0 | G15: 0
A16: Cash from Investing Activities | B16: =SUM(B14:B15) -> -240 | C16: =SUM(C14:C15) -> -260 | D16: =SUM(D14:D15) -> -285 | E16: =SUM(E14:E15) -> -302.1 | F16: =SUM(F14:F15) -> -323.247 | G16: =SUM(G14:G15) -> -345.87429
A18: FINANCING ACTIVITIES
A19: Net Debt Drawdown / (Repayment) | B19: 0 | C19: ='Balance Sheet'!C25-'Balance Sheet'!B25 -> -50 | D19: ='Balance Sheet'!D25-'Balance Sheet'!C25 -> -50 | E19: ='Balance Sheet'!E25-'Balance Sheet'!D25 -> 0 | F19: ='Balance Sheet'!F25-'Balance Sheet'!E25 -> 0 | G19: ='Balance Sheet'!G25-'Balance Sheet'!F25 -> 0
A20: Dividends Paid | B20: =-'Income Statement'!B21*Assumptions!$B$21 -> -240 | C20: =-'Income Statement'!C21*Assumptions!$B$21 -> -260 | D20: =-'Income Statement'!D21*Assumptions!$B$21 -> -300 | E20: =-'Income Statement'!E21*Assumptions!$B$21 -> -437.66625 | F20: =-'Income Statement'!F21*Assumptions!$B$21 -> -470.17976 | G20: =-'Income Statement'!G21*Assumptions!$B$21 -> -504.96922
A21: Cash from Financing Activities | B21: =SUM(B19:B20) -> -240 | C21: =SUM(C19:C20) -> -310 | D21: =SUM(D19:D20) -> -350 | E21: =SUM(E19:E20) -> -437.66625 | F21: =SUM(F19:F20) -> -470.17976 | G21: =SUM(G19:G20) -> -504.96922
A23: NET CHANGE IN CASH | B23: =B11+B16+B21 -> 220 | C23: =C11+C16+C21 -> 90 | D23: =D11+D16+D21 -> 115 | E23: =E11+E16+E21 -> 343.37378 | F23: =F11+F16+F21 -> 334.66929 | G23: =G11+G16+G21 -> 359.97302
A24: Opening Cash Balance | B24: ='Balance Sheet'!B6 -> 350 | C24: ='Balance Sheet'!B6 -> 350 | D24: ='Balance Sheet'!C6 -> 400 | E24: ='Balance Sheet'!D6 -> 450 | F24: ='Balance Sheet'!E6 -> 793.37378 | G24: ='Balance Sheet'!F6 -> 1128.0431
A25: Closing Cash Balance | B25: =B24+B23 -> 570 | C25: =C24+C23 -> 440 | D25: =D24+D23 -> 515 | E25: =E24+E23 -> 793.37378 | F25: =F24+F23 -> 1128.0431 | G25: =G24+G23 -> 1488.0161

Sheet DCF Valuation
A1: Next plc — DCF Valuation (£m)
A2: Enterprise Value → Equity Value → Implied Share Price
B3: FY2025E | C3: FY2026E | D3: FY2027E
A5: STEP 1 — FREE CASH FLOW TO FIRM (FCFF)
A6: EBIT (Operating Profit) | B6: ='Income Statement'!E15 -> 1238.61 | C6: ='Income Statement'!F15 -> 1325.3127 | D6: ='Income Statement'!G15 -> 1418.0846
A7: Tax on EBIT [EBIT × tax rate] | B7: =-B6*Assumptions!E8 -> -309.6525 | C7: =-C6*Assumptions!F8 -> -331.32818 | D7: =-D6*Assumptions!G8 -> -354.52115
A8: NOPAT (Net Operating Profit After Tax) | B8: =B6+B7 -> 928.9575 | C8: =C6+C7 -> 993.98453 | D8: =D6+D7 -> 1063.5634
A9: Add: Depreciation & Amortisation | B9: ='Income Statement'!E14 -> 271.89 | C9: ='Income Statement'!F14 -> 290.9223 | D9: ='Income Statement'!G14 -> 311.28686
A10: Less: Capital Expenditure | B10: ='Cash Flow'!E14 -> -302.1 | C10: ='Cash Flow'!F14 -> -323.247 | D10: ='Cash Flow'!G14 -> -345.87429
A11: Less: Change in Working Capital | B11: ='Cash Flow'!E7+'Cash Flow'!E8+'Cash Flow'!E9 -> -64.082466 | C11: ='Cash Flow'!F7+'Cash Flow'!F8+'Cash Flow'!F9 -> -103.18577 | D11: ='Cash Flow'!G7+'Cash Flow'!G8+'Cash Flow'!G9 -> -110.40878
A12: FREE CASH FLOW TO FIRM (FCFF) | B12: =B8+B9+B10+B11 -> 834.66503 | C12: =C8+C9+C10+C11 -> 858.47405 | D12: =D8+D9+D10+D11 -> 918.56724
A14: STEP 2 — WACC (Weighted Average Cost of Capital)
A15: Risk-Free Rate (10yr UK Gilt) | B15: 0.044
A16: Equity Risk Premium (ERP) | B16: 0.05
A17: Beta (Next plc — market risk) | B17: 0.75
A18: Cost of Equity [Rf + β × ERP] | B18: =B15+B17*B16 -> 0.0815
A20: Pre-Tax Cost of Debt | B20: 0.065
A21: Tax Rate | B21: =Assumptions!B8 -> 0.25
A22: After-Tax Cost of Debt [Kd×(1-t)] | B22: =B20*(1-B21) -> 0.04875
A24: Debt Weight [D/(D+E)] | B24: 0.3
A25: Equity Weight [E/(D+E)] | B25: =1-B24 -> 0.7
A27: WACC [Ke×We + Kd×Wd] | B27: =B18*B25+B22*B24 -> 0.071675
A29: STEP 3 — DISCOUNT CASH FLOWS + TERMINAL VALUE
A30: Discount Period (years) | B30: 1 | C30: 2 | D30: 3
A31: Discount Factor [1÷(1+WACC)^period] | B31: =1/(1+$B$27)^B30 -> 0.93311872 | C31: =1/(1+$B$27)^C30 -> 0.87071054 | D31: =1/(1+$B$27)^D30 -> 0.8124763
A32: Present Value of FCF | B32: =B12*B31 -> 778.84157 | C32: =C12*C31 -> 747.4824 | D32: =D12*D31 -> 746.31411
A34: Terminal Growth Rate (long-run) | B34: 0.025
A35: Terminal Year FCF (FY2027E) | B35: =D12 -> 918.56724
A36: Terminal Value [FCF×(1+g)÷(WACC−g)] | B36: =B35*(1+B34)/(B27-B34) -> 20172.071
A37: PV of Terminal Value | B37: =B36*(1/(1+B27)^3) -> 16389.33
A39: STEP 4 — ENTERPRISE VALUE → EQUITY VALUE
A40: Sum of PV of FCFs | B40: =SUM(B32:D32) -> 2272.6381
A41: PV of Terminal Value | B41: =B37 -> 16389.33
A42: ENTERPRISE VALUE (EV) | B42: =B40+B41 -> 18661.968
A43: Less: Net Debt [Debt − Cash] | B43: ='Balance Sheet'!D25-'Balance Sheet'!D6 -> 650
A44: EQUITY VALUE | B44: =B42-B43 -> 18011.968
A45: Shares Outstanding (m) | B45: 134
A46: IMPLIED SHARE PRICE (£) | B46: =B44/B45*1000 -> 134417.67
A47: Current Market Price (£) | B47: 137.7
A48: Upside / (Downside) | B48: =IFERROR(B46/B47-1,"-") -> 975.16318
...
